Workbook

Sheet INDEX
A1: Excel Intermediate to Advanced for Reporting & Analysis — Practice Workbook
A2: Adamjee Assurance Company Limited | One Day Training | 9:00 AM – 5:00 PM | Microsoft Excel 2016 | 63 problems, 63 datasets
A4: How to use: every topic has two sheets — a DATA sheet (the Adamjee dataset) and a TASK sheet (the problem statement plus a yellow area where you build your answer). Click a link below to jump.
A6: Topic | B6: Title | C6: Dataset | D6: Report Template
A7: Session 1: Advanced Lookup, Text & Date Functions
A8: 1.1 | B8: VLOOKUP with Approximate Match and Wildcards | C8: 1.1 Data | D8: 1.1 Report
A9: 1.2 | B9: HLOOKUP for Horizontal Data Tables | C9: 1.2 Data | D9: 1.2 Report
A10: 1.3 | B10: INDEX and MATCH (Single Criteria Lookup) | C10: 1.3 Data | D10: 1.3 Report
A11: 1.4 | B11: INDEX and MATCH (Two-Way Lookup) | C11: 1.4 Data | D11: 1.4 Report
A12: 1.5 | B12: INDEX and MATCH with Multiple Criteria (Array Formula, Ctrl+Shift+Enter) | C12: 1.5 Data | D12: 1.5 Report
A13: 1.6 | B13: OFFSET with MATCH for Dynamic Lookups | C13: 1.6 Data | D13: 1.6 Report
A14: 1.7 | B14: Handling Lookup Errors with IFERROR and IFNA | C14: 1.7 Data | D14: 1.7 Report
A15: 1.8 | B15: LEFT, RIGHT, MID | C15: 1.8 Data | D15: 1.8 Report
A16: 1.9 | B16: FIND and SEARCH | C16: 1.9 Data | D16: 1.9 Report
A17: 1.10 | B17: LEN, TRIM, CLEAN | C17: 1.10 Data | D17: 1.10 Report
A18: 1.11 | B18: SUBSTITUTE and REPLACE | C18: 1.11 Data | D18: 1.11 Report
A19: 1.12 | B19: CONCATENATE and the Ampersand (&) Operator | C19: 1.12 Data | D19: 1.12 Report
... A24: 1.17 | B24: Complex Date Calculations for Policy Lifecycle and Renewal Tracking | C24: 1.17 Data | D24: 1.17 Report
A25: Session 2: Array Formulas, Advanced Logic & Named Ranges
A26: 2.1 | B26: Understanding Array Formulas in Excel 2016 | C26: 2.1 Data | D26: 2.1 Report
A27: 2.2 | B27: Single-Cell Array Formulas for Multi-Criteria Calculations | C27: 2.2 Data | D27: 2.2 Report
A28: 2.3 | B28: Multi-Cell Array Formulas | C28: 2.3 Data | D28: 2.3 Report
A29: 2.4 | B29: SUM with IF Array for Conditional Totals | C29: 2.4 Data | D29: 2.4 Report
A30: 2.5 | B30: COUNT and AVERAGE with Array Conditions | C30: 2.5 Data | D30: 2.5 Report
A31: 2.6 | B31: Nested IF (Advanced Multi-Level Logic) | C31: 2.6 Data | D31: 2.6 Report
A32: 2.7 | B32: AND, OR Combined with IF | C32: 2.7 Data | D32: 2.7 Report
A33: 2.8 | B33: CHOOSE Function | C33: 2.8 Data | D33: 2.8 Report
A34: 2.9 | B34: SUMPRODUCT for Multi-Criteria Summing and Counting | C34: 2.9 Data | D34: 2.9 Report
A35: 2.10 | B35: SUMIFS, COUNTIFS, AVERAGEIFS (Multiple Criteria) | C35: 2.10 Data | D35: 2.10 Report
A36: 2.11 | B36: AGGREGATE Function (Ignoring Errors and Hidden Rows) | C36: 2.11 Data | D36: 2.11 Report
A37: 2.12 | B37: Creating and Managing Named Ranges | C37: 2.12 Data | D37: 2.12 Report
... A40: 2.15 | B40: INDIRECT Function for Dynamic References | C40: 2.15 Data | D40: 2.15 Report
A41: Session 3: Advanced Pivot Tables, Power Query & What-If Analysis
A42: 3.1 | B42: Calculated Fields and Calculated Items | C42: 3.1 Data | D42: 3.1 Report
A43: 3.2 | B43: Grouping Data (Dates by Month/Quarter/Year, Numbers, Text) | C43: 3.2 Data | D43: 3.2 Report
A44: 3.3 | B44: Show Values As (% of Grand Total, % of Parent, Running Total, Difference From) | C44: 3.3 Data | D44: 3.3 Report
A45: 3.4 | B45: Slicers and Timelines Connected to Multiple Pivot Tables | C45: 3.4 Data | D45: 3.4 Report
A46: 3.5 | B46: Pivot Table from Multiple Sheets Using Consolidation | C46: 3.5 Data | D46: 3.5 Report
A47: 3.6 | B47: Conditional Formatting Applied to Pivot Tables | C47: 3.6 Data | D47: 3.6 Report
A48: 3.7 | B48: Accessing Get & Transform from the Data Tab in Excel 2016 | C48: 3.7 Data | D48: 3.7 Report
...

Sheet 1.1 Data
A1: Dataset 1.1 — VLOOKUP with Approximate Match and Wildcards
A2: Session 1: Advanced Lookup, Text & Date Functions | Part A: Advanced Lookup Functions | Adamjee Assurance Company Limited (Pakistan) — training data, figures in PKR
A4: Table A — Motor Own-Damage Banded Rate Card (ascending order required)
A5: Sum Insured From (PKR) | B5: Band | C5: Rate Applied | D5: No-Claim Discount
A6: 0 | B6: Band E | C6: 0.0285 | D6: 0
A7: 2000000 | B7: Band D | C7: 0.024 | D7: 0.05
A8: 5000000 | B8: Band C | C8: 0.0195 | D8: 0.075
A9: 10000000 | B9: Band B | C9: 0.016 | D9: 0.1
A10: 25000000 | B10: Band A | C10: 0.0125 | D10: 0.15
A11: 50000000 | B11: Band A+ | C11: 0.0095 | D11: 0.2
A13: Table B — Quotation Requests received at Karachi Main (UW Desk)
A14: Quote Ref | B14: Client Name (as registered) | C14: Client Code | D14: Vehicle / Asset | E14: Sum Insured (PKR)
A15: QT-2024-0451 | B15: Gul Ahmed Textile Mills Ltd | C15: KHI-CORP-0100 | D15: Toyota Hilux Revo 2023 | E15: 8450000
A16: QT-2024-0452 | B16: Lucky Cement Limited | C16: KHI-CORP-0102 | D16: Fleet – 6 x Suzuki Bolan | E16: 4320000
A17: QT-2024-0453 | B17: Ahmed Raza Qureshi | C17: KHI-INDV-0107 | D17: Honda Civic Oriel 2022 | E17: 6900000
A18: QT-2024-0454 | B18: Indus Motor Company Ltd | C18: KHI-CORP-0110 | D18: Executive fleet – 4 x Fortuner | E18: 34800000
A19: QT-2024-0455 | B19: Fatima Siddiqui | C19: LHR-INDV-0113 | D19: Suzuki Alto VXL 2024 | E19: 1950000
A20: QT-2024-0456 | B20: Interloop Limited | C20: FSD-CORP-0118 | D20: Staff transport buses – 3 units | E20: 22500000
A21: QT-2024-0457 | B21: K-Electric Limited | C21: KHI-CORP-0121 | D21: Utility fleet – 18 vehicles | E21: 61200000
A22: QT-2024-0458 | B22: Bilal Ahmed Khan | C22: ISB-INDV-0125 | D22: Kia Sportage AWD 2023 | E22: 9990000
A24: Table C — Partial names typed by the call centre (wildcard search list)
A25: Search Text Entered | B25: What the agent meant
A26: Gul Ahmed* | B26: Any client starting with Gul Ahmed
A27: *Cement* | B27: Any client containing Cement
A28: Interloop?Limited | B28: One unknown character between the two words
A29: *Electric* | B29: Any client containing Electric
A31: Note: This is simulated training data modelled on Adamjee Assurance general insurance operations. It is not actual company data.

Sheet 1.1 Report
A1: ADAMJEE ASSURANCE COMPANY LIMITED
A2: Motor Quotation Register — 8 quotes priced today
A3: Prepared for: | B3: Head of Motor Underwriting, Karachi Main
A4: Prepared by:
A5: Reporting date: | B5: As at reporting date shown on the dataset
A7: Eight quotation requests arrived this morning and the broker has promised all eight clients a price before close of business. The rate card is banded by sum insured and none of the eight sums insured lands exactly on a band edge. The junior underwriter priced three of them by eye yesterday and got two wrong.
A9: Source data: '1.1 Data' (click to open)
A11: Navy headers below = data linked live from the dataset sheet. Gold headers = blank — build your formula here.
A12: Quote Ref | B12: Client Name | C12: Sum Insured | D12: Band | E12: Rate Applied | F12: No-Claim Discount | G12: Gross Premium
A13: ='1.1 Data'!A15 | B13: ='1.1 Data'!B15 | C13: ='1.1 Data'!E15
A14: ='1.1 Data'!A16 | B14: ='1.1 Data'!B16 | C14: ='1.1 Data'!E16
A15: ='1.1 Data'!A17 | B15: ='1.1 Data'!B17 | C15: ='1.1 Data'!E17
A16: ='1.1 Data'!A18 | B16: ='1.1 Data'!B18 | C16: ='1.1 Data'!E18
A17: ='1.1 Data'!A19 | B17: ='1.1 Data'!B19 | C17: ='1.1 Data'!E19
A18: ='1.1 Data'!A20 | B18: ='1.1 Data'!B20 | C18: ='1.1 Data'!E20
A19: ='1.1 Data'!A21 | B19: ='1.1 Data'!B21 | C19: ='1.1 Data'!E21
A20: ='1.1 Data'!A22 | B20: ='1.1 Data'!B22 | C20: ='1.1 Data'!E22
A21: TOTAL / RESULT
A23: HOW TO WORK: navy-header columns are linked live from the dataset sheet — click any cell to see the formula. Gold-header columns are blank and shaded yellow — build the required formula there and copy it down every row, then complete the TOTAL / RESULT row at the foot.
A25: FURTHER REQUESTS ON THIS DATASET
A26: # | B26: Request | C26: Requested by | D26: Report / figure required | E26: Your formula or answer
A27: 1 | B27: Rate Card Sensitivity Note for the Underwriting Committee | C27: Chief Underwriting Officer | D27: A two-column comparison: Quote Ref | Premium at current rates | Premium at rates +0.25% | Difference | % change. One total line. The band rates must sit in cells so the Committee can type a new rate and watch the whole schedule move.
A28: 2 | B28: Call Centre Client Lookup — partial names | C28: Manager, Customer Contact Centre | D28: A lookup panel with the four search patterns down the side and these columns: Search Text | Client Name Matched | Client Code | Sum Insured on file. One formula copied down all four rows — the agent types a new pattern in the search cell and the answers appear.
A29: 3 | B29: Underwriting Exception Report — borderline sums insured | C29: Chief Underwriting Officer | D29: An exception list showing: Quote Ref | Sum Insured | Band applied | Distance to the next band up (PKR) | Flag 'Near boundary' where within 10%. Sorted with the closest to a boundary first.
A30: 4 | B30: Handover note for the new underwriting assistant | C30: Head of Motor Underwriting | D30: A five-line written note, in the yellow box, explaining: why the rate card must stay sorted ascending, what the 4th argument of VLOOKUP does, and what to check if a premium comes out obviously wrong.

Sheet 1.2 Data
A1: Dataset 1.2 — HLOOKUP for Horizontal Data Tables
A2: Session 1: Advanced Lookup, Text & Date Functions | Part A: Advanced Lookup Functions | Adamjee Assurance Company Limited (Pakistan) — training data, figures in PKR
A4: Table A — Gross Written Premium by Branch, 2024 (months across the top)
A5: Branch | B5: Jan-2024 | C5: Feb-2024 | D5: Mar-2024 | E5: Apr-2024 | F5: May-2024 | G5: Jun-2024 | H5: Jul-2024 | I5: Aug-2024 | J5: Sep-2024 | K5: Oct-2024 | L5: Nov-2024 | M5: Dec-2024
A6: Karachi Main | B6: 8478000 | C6: 5658000 | D6: 13810000 | E6: 4380000 | F6: 11934000 | G6: 9160000 | H6: 4145000 | I6: 11471000 | J6: 3811000 | K6: 10268000 | L6: 4338000 | M6: 4678000
A7: Lahore Gulberg | B7: 10119000 | C7: 16677000 | D7: 5217000 | E7: 6838000 | F7: 13427000 | G7: 18647000 | H7: 12606000 | I7: 9665000 | J7: 19112000 | K7: 3959000 | L7: 17193000 | M7: 7920000
A8: Islamabad Blue Area | B8: 5551000 | C8: 5120000 | D8: 8228000 | E8: 16502000 | F8: 6145000 | G8: 12680000 | H8: 13614000 | I8: 9270000 | J8: 12128000 | K8: 4223000 | L8: 4171000 | M8: 6557000
A9: Faisalabad | B9: 14290000 | C9: 10169000 | D9: 8320000 | E9: 12744000 | F9: 10586000 | G9: 8086000 | H9: 16148000 | I9: 14593000 | J9: 7178000 | K9: 12563000 | L9: 11760000 | M9: 17464000
A10: Multan | B10: 15089000 | C10: 7893000 | D10: 19176000 | E10: 5124000 | F10: 10015000 | G10: 15541000 | H10: 5677000 | I10: 11170000 | J10: 3839000 | K10: 14091000 | L10: 15662000 | M10: 12540000
A11: Peshawar | B11: 17470000 | C11: 8314000 | D11: 14533000 | E11: 12888000 | F11: 12652000 | G11: 10636000 | H11: 16891000 | I11: 18598000 | J11: 10927000 | K11: 14025000 | L11: 4188000 | M11: 14634000
A13: Table B — Claims Paid by Branch, 2024 (same horizontal layout)
A14: Branch | B14: Jan-2024 | C14: Feb-2024 | D14: Mar-2024 | E14: Apr-2024 | F14: May-2024 | G14: Jun-2024 | H14: Jul-2024 | I14: Aug-2024 | J14: Sep-2024 | K14: Oct-2024 | L14: Nov-2024 | M14: Dec-2024
A15: Karachi Main | B15: 7738000 | C15: 8827000 | D15: 6156000 | E15: 6066000 | F15: 4874000 | G15: 10967000 | H15: 3822000 | I15: 2397000 | J15: 3536000 | K15: 3530000 | L15: 4206000 | M15: 3605000
A16: Lahore Gulberg | B16: 1987000 | C16: 4187000 | D16: 4041000 | E16: 6649000 | F16: 2936000 | G16: 1614000 | H16: 2945000 | I16: 6378000 | J16: 4824000 | K16: 8308000 | L16: 9010000 | M16: 5085000
A17: Islamabad Blue Area | B17: 1903000 | C17: 8252000 | D17: 8532000 | E17: 4900000 | F17: 7548000 | G17: 3920000 | H17: 10140000 | I17: 9321000 | J17: 8898000 | K17: 10534000 | L17: 3251000 | M17: 6407000
A18: Faisalabad | B18: 8286000 | C18: 8994000 | D18: 4841000 | E18: 2299000 | F18: 7225000 | G18: 1956000 | H18: 8024000 | I18: 970000 | J18: 5490000 | K18: 5745000 | L18: 2109000 | M18: 5749000
A19: Multan | B19: 5950000 | C19: 4627000 | D19: 9952000 | E19: 9647000 | F19: 9894000 | G19: 3373000 | H19: 1161000 | I19: 4703000 | J19: 2047000 | K19: 8022000 | L19: 3555000 | M19: 2196000
A20: Peshawar | B20: 3765000 | C20: 4974000 | D20: 8327000 | E20: 5556000 | F20: 3941000 | G20: 7741000 | H20: 1357000 | I20: 3012000 | J20: 7843000 | K20: 8495000 | L20: 1923000 | M20: 1571000
A22: Table C — Report request parameters
A23: Parameter | B23: Value
A24: Reporting Month | B24: Sep-2024
A25: Branch under review | B25: Lahore Gulberg
A26: Comparison Month | B26: Mar-2024
A28: Note: This is simulated training data modelled on Adamjee Assurance general insurance operations. It is not actual company data.

Sheet 1.2 Report
A1: ADAMJEE ASSURANCE COMPANY LIMITED
A2: September Branch Premium Flash Report
A3: Prepared for: | B3: Chief Financial Officer
A4: Prepared by:
A5: Reporting date: | B5: As at reporting date shown on the dataset
A7: Finance publishes the monthly GWP file with months running across the top and refuses to change the layout. The CFO wants a one-page flash for September that pulls from that file automatically, because last month someone copied the August column by mistake and the flash went out with the wrong figures.
A9: Source data: '1.2 Data' (click to open)
A11: DELIVERABLE CHECKLIST
A12: # | B12: Deliverable | C12: Report specification | D12: Requested by | E12: Done?
A13: 1 | B13: September Branch Premium Flash Report | C13: A flash report block: Reporting Month (input cell) | Branch (input cell) | GWP | Claims Paid | Loss Ratio. All four output cells must be formulas driven by the two input cells — typing 'Oct-2024' into the month cell must refresh the entire block. | D13: Chief Financial Officer
A14: 2 | B14: Branch League Table for the Monday management call | C14: A league table with one row per branch and these columns: Branch | GWP for the selected month | Claims Paid | Loss Ratio | Rank by GWP. Driven by a single month input cell. Loss ratio formatted 0.0%. | D14: Regional Head — South
A15: 3 | B15: Month-on-Month Variance Commentary Pack | C15: A variance block: Branch | GWP Reporting Month | GWP Comparison Month | Variance (PKR) | Variance % | Direction (Up/Down/Flat). Both month names come from parameter cells. | D15: Head of Management Reporting
A16: 4 | B16: Layout risk memo to the Finance systems team | C16: A short memo, in the yellow box, stating: which formula broke, why a hard-coded row_num is fragile, the one-line fix, and when INDEX/MATCH should be used instead of HLOOKUP altogether. | D16: Head of Internal Audit
A18: BUILD YOUR REPORT / OUTPUT BELOW (pivot, chart, macro output, or model — as required above)
A34: HOW TO WORK: build the requested output in the blank area above (or insert a pivot table / chart / macro-driven control here), tick each deliverable off in the checklist, and record any formula or setting worth remembering in the specification column.

Sheet 1.3 Data
A1: Dataset 1.3 — INDEX and MATCH (Single Criteria Lookup)
A2: Session 1: Advanced Lookup, Text & Date Functions | Part A: Advanced Lookup Functions | Adamjee Assurance Company Limited (Pakistan) — training data, figures in PKR
A4: Table A — Policy Master Extract (Client Code deliberately placed left of Policy No)
A5: Client Code | B5: Policy No | C5: Client Name | D5: Branch | E5: Product | F5: Expiry Date | G5: Sum Insured (PKR) | H5: Gross Premium (PKR)
A6: KHI-CORP-0100 | B6: ADM-FIR-KHI-2024-1001 | C6: Gul Ahmed Textile Mills Ltd | D6: Karachi Main | E6: Fire & Property | F6: 45896 | G6: 4500000 | H6: 96000
A7: LHR-CORP-0101 | B7: ADM-TRV-LHR-2024-1002 | C7: Packages Limited | D7: Lahore Gulberg | E7: Travel | F7: 45865 | G7: 12000000 | H7: 201000
A8: ISB-INDV-0102 | B8: ADM-MTR-ISB-2024-1003 | C8: Bilal Ahmed Khan | D8: Islamabad Blue Area | E8: Motor | F8: 45868 | G8: 65000000 | H8: 1397000
A9: FSD-CORP-0103 | B9: ADM-HLT-FSD-2024-1004 | C9: Attock Refinery Limited | D9: Faisalabad | E9: Health | F9: 45934 | G9: 18500000 | H9: 305000
A10: MUL-CORP-0104 | B10: ADM-MSC-MUL-2024-1005 | C10: Descon Engineering Ltd | D10: Multan | E10: Miscellaneous | F10: 45895 | G10: 4500000 | H10: 75000
A11: PEW-INDV-0105 | B11: ADM-MAR-PEW-2024-1006 | C11: Hina Farooq | D11: Peshawar | E11: Marine Cargo | F11: 45834 | G11: 25000000 | H11: 380000
A12: QTA-CORP-0106 | B12: ADM-ENG-QTA-2024-1007 | C12: Indus Motor Company Ltd | D12: Quetta | E12: Engineering | F12: 45855 | G12: 18500000 | H12: 227000
A13: HYD-CORP-0107 | B13: ADM-FIR-HYD-2024-1008 | C13: Nishat Mills Limited | D13: Hyderabad | E13: Fire & Property | F13: 45874 | G13: 25000000 | H13: 290000
A14: SKT-INDV-0108 | B14: ADM-TRV-SKT-2024-1009 | C14: Imran Aslam Sheikh | D14: Sialkot | E14: Travel | F14: 45773 | G14: 7500000 | H14: 37000
A15: RWP-CORP-0109 | B15: ADM-MTR-RWP-2024-1010 | C15: Engro Polymer & Chemicals | D15: Rawalpindi | E15: Motor | F15: 45788 | G15: 65000000 | H15: 760000
A16: KHI-CORP-0110 | B16: ADM-HLT-KHI-2024-1011 | C16: Interloop Limited | D16: Karachi Main | E16: Health | F16: 45871 | G16: 90000000 | H16: 603000
A17: LHR-INDV-0111 | B17: ADM-MSC-LHR-2024-1012 | C17: Mehwish Anwar | D17: Lahore Gulberg | E17: Miscellaneous | F17: 45776 | G17: 40000000 | H17: 512000
... A25: RWP-CORP-0119 | B25: ADM-MAR-RWP-2024-1020 | C25: Thal Limited | D25: Rawalpindi | E25: Marine Cargo | F25: 45868 | G25: 7500000 | H25: 181000
A27: Table B — Servicing queue (policy numbers received from branches)
A28: Query Ref | B28: Policy No | C28: Query Type
A29: SRV-1001 | B29: ADM-HLT-FSD-2024-1004 | C29: Premium confirmation
A30: SRV-1002 | B30: ADM-MSC-LHR-2024-1012 | C30: Expiry confirmation
A31: SRV-1003 | B31: ADM-FIR-HYD-2024-1008 | C31: Client code required
A32: SRV-1004 | B32: ADM-MSC-SKT-2024-1019 | C32: Branch transfer
A33: SRV-1005 | B33: ADM-FIR-KHI-2024-1001 | C33: Sum insured endorsement
A35: Note: This is simulated training data modelled on Adamjee Assurance general insurance operations. It is not actual company data.

Sheet 1.3 Report
A1: ADAMJEE ASSURANCE COMPANY LIMITED
A2: Policy Servicing Queue — daily response file
A3: Prepared for: | B3: Manager, Policy Servicing
A4: Prepared by:
A5: Reporting date: | B5: As at reporting date shown on the dataset
A7: Five branch queries came in overnight, each quoting only a policy number. The team currently opens the master file and scrolls to each one by hand, which takes about ten minutes per query and is the main reason the 24-hour service standard was missed eleven times last month.
A9: Source data: '1.3 Data' (click to open)
A11: Navy headers below = data linked live from the dataset sheet. Gold headers = blank — build your formula here.
A12: Query Ref | B12: Policy No | C12: Client Name | D12: Client Code | E12: Branch | F12: Expiry Date | G12: Sum Insured | H12: Gross Premium
A13: ='1.3 Data'!A29 | B13: ='1.3 Data'!B29
A14: ='1.3 Data'!A30 | B14: ='1.3 Data'!B30
A15: ='1.3 Data'!A31 | B15: ='1.3 Data'!B31
A16: ='1.3 Data'!A32 | B16: ='1.3 Data'!B32
A17: ='1.3 Data'!A33 | B17: ='1.3 Data'!B33
A18: TOTAL / RESULT
A20: HOW TO WORK: navy-header columns are linked live from the dataset sheet — click any cell to see the formula. Gold-header columns are blank and shaded yellow — build the required formula there and copy it down every row, then complete the TOTAL / RESULT row at the foot.
A22: FURTHER REQUESTS ON THIS DATASET
A23: # | B23: Request | C23: Requested by | D23: Report / figure required | E23: Your formula or answer
A24: 1 | B24: Endorsement confirmation letter data | C24: Branch Manager, Karachi Main | D24: A single-row data block feeding the letter: Client Name | Client Code | Policy No | Product | Current Sum Insured | Expiry Date. Each field a formula keyed off the policy number in one cell, so changing that one cell produces the next client's letter.
A25: 2 | B25: Servicing Turnaround Dashboard — named range version | C25: Head of Operations | D25: The same response file rebuilt using named ranges (Policy_No, Client_Name, Gross_Premium and so on) instead of cell addresses, plus a one-line note confirming the results are identical to the address-based version.
A26: 3 | B26: Data integrity check before the file goes back to branches | C26: Head of Internal Audit | D26: A validation column: Match Type Used | Row Position Returned | Status ('Exact match confirmed' or 'Check'). Plus a one-line explanation of what MATCH's third argument was set to and what would happen at 1.

Sheet 1.4 Data
A1: Dataset 1.4 — INDEX and MATCH (Two-Way Lookup)
A2: Session 1: Advanced Lookup, Text & Date Functions | Part A: Advanced Lookup Functions | Adamjee Assurance Company Limited (Pakistan) — training data, figures in PKR
A4: Table A — Gross Written Premium 2024, Branch (rows) x Product (columns), PKR
A5: Branch | B5: Motor | C5: Fire & Property | D5: Marine Cargo | E5: Health | F5: Travel | G5: Engineering | H5: Miscellaneous
A6: Karachi Main | B6: 8344000 | C6: 12892000 | D6: 8101000 | E6: 7888000 | F6: 2473000 | G6: 6011000 | H6: 17784000
A7: Lahore Gulberg | B7: 12007000 | C7: 6810000 | D7: 15984000 | E7: 8354000 | F7: 8703000 | G7: 4393000 | H7: 13413000
A8: Islamabad Blue Area | B8: 13497000 | C8: 9086000 | D8: 4640000 | E8: 9170000 | F8: 15357000 | G8: 18314000 | H8: 5663000
A9: Faisalabad | B9: 22522000 | C9: 19592000 | D9: 13301000 | E9: 23640000 | F9: 3472000 | G9: 12220000 | H9: 7205000
A10: Multan | B10: 2425000 | C10: 5760000 | D10: 4235000 | E10: 9483000 | F10: 11513000 | G10: 18303000 | H10: 21853000
A11: Peshawar | B11: 4046000 | C11: 20673000 | D11: 11464000 | E11: 1358000 | F11: 16554000 | G11: 20109000 | H11: 13079000
A12: Quetta | B12: 17499000 | C12: 18867000 | D12: 5816000 | E12: 20252000 | F12: 12794000 | G12: 16694000 | H12: 23047000
A13: Hyderabad | B13: 12490000 | C13: 10235000 | D13: 11525000 | E13: 6239000 | F13: 2208000 | G13: 17135000 | H13: 11433000
A14: Sialkot | B14: 16248000 | C14: 13181000 | D14: 2928000 | E14: 7310000 | F14: 19592000 | G14: 3867000 | H14: 15522000
A15: Rawalpindi | B15: 13409000 | C15: 9436000 | D15: 8661000 | E15: 19270000 | F15: 15087000 | G15: 12038000 | H15: 18244000
A17: Table B — Claims Paid 2024, Branch (rows) x Product (columns), PKR
A18: Branch | B18: Motor | C18: Fire & Property | D18: Marine Cargo | E18: Health | F18: Travel | G18: Engineering | H18: Miscellaneous
A19: Karachi Main | B19: 11109000 | C19: 11296000 | D19: 3983000 | E19: 5818000 | F19: 11580000 | G19: 7108000 | H19: 3751000
A20: Lahore Gulberg | B20: 1743000 | C20: 3647000 | D20: 7438000 | E20: 12995000 | F20: 10006000 | G20: 6118000 | H20: 10598000
A21: Islamabad Blue Area | B21: 2805000 | C21: 11269000 | D21: 3924000 | E21: 1677000 | F21: 2444000 | G21: 3365000 | H21: 12545000
A22: Faisalabad | B22: 3975000 | C22: 1247000 | D22: 13522000 | E22: 11843000 | F22: 3654000 | G22: 12623000 | H22: 13699000
A23: Multan | B23: 1345000 | C23: 5307000 | D23: 2546000 | E23: 5170000 | F23: 11021000 | G23: 11352000 | H23: 8158000
A24: Peshawar | B24: 10677000 | C24: 6177000 | D24: 8770000 | E24: 3550000 | F24: 698000 | G24: 10846000 | H24: 10732000
A25: Quetta | B25: 5061000 | C25: 7744000 | D25: 6553000 | E25: 12674000 | F25: 5261000 | G25: 1000000 | H25: 3084000
A26: Hyderabad | B26: 1135000 | C26: 10949000 | D26: 6545000 | E26: 11015000 | F26: 1384000 | G26: 239000 | H26: 1306000
A27: Sialkot | B27: 11527000 | C27: 8888000 | D27: 3097000 | E27: 9878000 | F27: 3390000 | G27: 11634000 | H27: 13313000
A28: Rawalpindi | B28: 8216000 | C28: 10831000 | D28: 5962000 | E28: 7486000 | F28: 5498000 | G28: 3874000 | H28: 11521000
A30: Table C — Query cell inputs
A31: Parameter | B31: Value
A32: Branch | B32: Multan
A33: Product | B33: Marine Cargo
A35: Note: This is simulated training data modelled on Adamjee Assurance general insurance operations. It is not actual company data.

Sheet 1.4 Report
A1: ADAMJEE ASSURANCE COMPANY LIMITED
A2: Branch x Product Premium Query Panel
A3: Prepared for: | B3: Regional Head — Central
A4: Prepared by:
A5: Reporting date: | B5: As at reporting date shown on the dataset
A7: The Regional Head keeps a printed Branch x Product grid on his desk and reads the wrong cell about once a week because the grid is seven columns wide and ten rows deep. He has asked for a single query cell instead.
A9: Source data: '1.4 Data' (click to open)
A11: DELIVERABLE CHECKLIST
A12: # | B12: Deliverable | C12: Report specification | D12: Requested by | E12: Done?
A13: 1 | B13: Branch x Product Premium Query Panel | C13: A query panel at the top of the report: two input cells (Branch, Product) and three output cells (GWP, Claims Paid, Loss Ratio). Changing either input must refresh all three outputs. Loss ratio formatted 0.0%. | D13: Regional Head — Central
A14: 2 | B14: Error-proofing the panel before it goes to the Regional Heads | C14: The same panel with: drop-down lists on both input cells sourced from the row and column labels, and every output wrapped so an invalid entry reads 'Not found' rather than an error code. | D14: Head of MIS
A15: 3 | B15: Worst-Performing Product Line — quarterly underwriting review | C15: A ranked table: Product | Total GWP | Total Claims | Loss Ratio | Rank (1 = worst). Plus a single highlighted cell naming the single worst Branch/Product combination in the whole grid and its loss ratio. | D15: Chief Underwriting Officer
A16: 4 | B16: Portfolio Steering Note | C16: A three-line written recommendation in the yellow box naming the two lines, the loss ratio evidence for each, and one sentence on what you would do about it. | D16: Chief Underwriting Officer
A18: BUILD YOUR REPORT / OUTPUT BELOW (pivot, chart, macro output, or model — as required above)
A34: HOW TO WORK: build the requested output in the blank area above (or insert a pivot table / chart / macro-driven control here), tick each deliverable off in the checklist, and record any formula or setting worth remembering in the specification column.

Sheet 1.5 Data
A1: Dataset 1.5 — INDEX and MATCH with Multiple Criteria (Array Formula, Ctrl+Shift+Enter)
A2: Session 1: Advanced Lookup, Text & Date Functions | Part A: Advanced Lookup Functions | Adamjee Assurance Company Limited (Pakistan) — training data, figures in PKR
A4: Table A — Endorsement Register 2024
A5: Policy No | B5: Endorsement Type | C5: Effective Month | D5: Branch | E5: Premium Impact (PKR) | F5: Handled By
A6: ADM-FIR-KHI-2024-1001 | B6: Sum Insured Increase | C6: Jan-2024 | D6: Karachi Main | E6: 185000 | F6: Tariq Jameel
A7: ADM-TRV-LHR-2024-1002 | B7: Vehicle Change | C7: Jan-2024 | D7: Lahore Gulberg | E7: -42000 | F7: Nadia Hassan
A8: ADM-MTR-ISB-2024-1003 | B8: Sum Insured Increase | C8: Feb-2024 | D8: Islamabad Blue Area | E8: 260000 | F8: Salman Shah
A9: ADM-HLT-FSD-2024-1004 | B9: Address Change | C9: Feb-2024 | D9: Faisalabad | E9: 0 | F9: Komal Bashir
A10: ADM-MSC-MUL-2024-1005 | B10: Cancellation Refund | C10: Mar-2024 | D10: Multan | E10: -310000 | F10: Waqar Younis Khan
A11: ADM-MAR-PEW-2024-1006 | B11: Sum Insured Increase | C11: Mar-2024 | D11: Peshawar | E11: 96500 | F11: Amna Zubair
A12: ADM-ENG-QTA-2024-1007 | B12: Add Driver | C12: Apr-2024 | D12: Quetta | E12: 18000 | F12: Rizwan Ali Soomro
A13: ADM-FIR-HYD-2024-1008 | B13: Sum Insured Increase | C13: Apr-2024 | D13: Hyderabad | E13: 412000 | F13: Farhan Dar
A14: ADM-TRV-SKT-2024-1009 | B14: Vehicle Change | C14: May-2024 | D14: Sialkot | E14: -75000 | F14: Sobia Naz
A15: ADM-MTR-RWP-2024-1010 | B15: Extension of Period | C15: May-2024 | D15: Rawalpindi | E15: 133000 | F15: Junaid Akram
A16: ADM-HLT-KHI-2024-1011 | B16: Sum Insured Increase | C16: Jun-2024 | D16: Karachi Main | E16: 204500 | F16: Hamid Raza
A17: ADM-MSC-LHR-2024-1012 | B17: Cancellation Refund | C17: Jun-2024 | D17: Lahore Gulberg | E17: -88000 | F17: Nimra Saleem
... A25: ADM-MAR-RWP-2024-1020 | B25: Sum Insured Increase | C25: Oct-2024 | D25: Rawalpindi | E25: 190000 | F25: Farhan Dar
A27: Table B — Three-criteria query
A28: Criteria | B28: Value
A29: Policy No | B29: ADM-ENG-QTA-2024-1007
A30: Endorsement Type | B30: Add Driver
A31: Effective Month | B31: Apr-2024
A33: Note: This is simulated training data modelled on Adamjee Assurance general insurance operations. It is not actual company data.

Sheet 1.5 Report
A1: ADAMJEE ASSURANCE COMPANY LIMITED
A2: Cancellation Refund Reconciliation
A3: Prepared for: | B3: Finance Manager — Premium Accounting
A4: Prepared by:
A5: Reporting date: | B5: As at reporting date shown on the dataset
A7: Three cancellation refunds were posted in the ledger this quarter and Finance cannot match two of them to the endorsement register because the same policy also had a sum insured increase in the same month.
A9: Source data: '1.5 Data' (click to open)
A11: Navy headers below = data linked live from the dataset sheet. Gold headers = blank — build your formula here.
A12: Policy No | B12: Month | C12: Cancellation Refund from the register | D12: Amount in ledger (entered by you) | E12: Difference | F12: Status (
A13: ='1.5 Data'!A6 | B13: ='1.5 Data'!C6
A14: ='1.5 Data'!A7 | B14: ='1.5 Data'!C7
A15: ='1.5 Data'!A8 | B15: ='1.5 Data'!C8
A16: ='1.5 Data'!A9 | B16: ='1.5 Data'!C9
A17: ='1.5 Data'!A10 | B17: ='1.5 Data'!C10
A18: ='1.5 Data'!A11 | B18: ='1.5 Data'!C11
A19: ='1.5 Data'!A12 | B19: ='1.5 Data'!C12
A20: ='1.5 Data'!A13 | B20: ='1.5 Data'!C13
A21: ='1.5 Data'!A14 | B21: ='1.5 Data'!C14
A22: ='1.5 Data'!A15 | B22: ='1.5 Data'!C15
A23: ='1.5 Data'!A16 | B23: ='1.5 Data'!C16
A24: ='1.5 Data'!A17 | B24: ='1.5 Data'!C17
... A32: ='1.5 Data'!A25 | B32: ='1.5 Data'!C25
A33: TOTAL / RESULT
A35: HOW TO WORK: navy-header columns are linked live from the dataset sheet — click any cell to see the formula. Gold-header columns are blank and shaded yellow — build the required formula there and copy it down every row, then complete the TOTAL / RESULT row at the foot.
A37: FURTHER REQUESTS ON THIS DATASET
A38: # | B38: Request | C38: Requested by | D38: Report / figure required | E38: Your formula or answer
A39: 1 | B39: Endorsement Premium Impact Statement | C39: Manager, Policy Administration | D39: A statement block keyed on three criteria (Policy No, Endorsement Type, Effective Month) returning: Premium Impact | Branch | Handled By. Changing any of the three criteria cells must return the correct single record.
A40: 2 | B40: Endorsement Audit Trail — five disputed records | C40: Head of Internal Audit | D40: An audit schedule: five rows, each with Policy No | Endorsement Type | Effective Month as inputs, and Premium Impact | Handled By as formula outputs. One formula pattern copied down all five rows.
A41: 3 | B41: Robustness test before release | C41: Head of MIS | D41: Evidence of two tests, recorded in the yellow box: what the formula returns for a combination that does not exist, and what it returns after your fix. State which wrapper you used and why.

Sheet 1.6 Data
A1: Dataset 1.6 — OFFSET with MATCH for Dynamic Lookups
A2: Session 1: Advanced Lookup, Text & Date Functions | Part A: Advanced Lookup Functions | Adamjee Assurance Company Limited (Pakistan) — training data, figures in PKR
A4: Table A — Monthly Gross Written Premium, Adamjee Assurance (all branches), PKR
A5: Month | B5: Gross Written Premium | C5: Claims Paid | D5: Net Premium Earned | E5: Policies Issued
A6: Jan-2024 | B6: 70997000 | C6: 29629000 | D6: 58217540 | E6: 1200
A7: Feb-2024 | B7: 53831000 | C7: 39861000 | D7: 44141420 | E7: 1292
A8: Mar-2024 | B8: 69284000 | C8: 41849000 | D8: 56812880 | E8: 1384
A9: Apr-2024 | B9: 58476000 | C9: 35117000 | D9: 47950320 | E9: 1476
A10: May-2024 | B10: 64759000 | C10: 36418000 | D10: 53102380 | E10: 1348
A11: Jun-2024 | B11: 74750000 | C11: 29571000 | D11: 61295000 | E11: 1440
A12: Jul-2024 | B12: 69081000 | C12: 27449000 | D12: 56646420 | E12: 1532
A13: Aug-2024 | B13: 74767000 | C13: 26781000 | D13: 61308940 | E13: 1624
A14: Sep-2024 | B14: 56995000 | C14: 32638000 | D14: 46735900 | E14: 1496
A15: Oct-2024 | B15: 59129000 | C15: 44634000 | D15: 48485780 | E15: 1588
A16: Nov-2024 | B16: 57312000 | C16: 24054000 | D16: 46995840 | E16: 1680
A17: Dec-2024 | B17: 63793000 | C17: 24613000 | D17: 52310260 | E17: 1772
A19: Table B — Rolling window controls
A20: Control | B20: Value
A21: Start Month | B21: Apr-2024
A22: Number of Months | B22: 3
A23: Measure required | B23: Gross Written Premium
A25: Note: This is simulated training data modelled on Adamjee Assurance general insurance operations. It is not actual company data.

Sheet 1.6 Report
A1: ADAMJEE ASSURANCE COMPANY LIMITED
A2: Rolling 3-Month Premium Report
A3: Prepared for: | B3: Chief Financial Officer
A4: Prepared by:
A5: Reporting date: | B5: As at reporting date shown on the dataset
A7: The CFO reviews momentum on a rolling three-month basis, not year-to-date, because year-to-date hides a bad quarter. At present an analyst rewrites the SUM range every month and in July the range was left on the previous window, so the report understated premium by a full month.
A9: Source data: '1.6 Data' (click to open)
A11: DELIVERABLE CHECKLIST
A12: # | B12: Deliverable | C12: Report specification | D12: Requested by | E12: Done?
A13: 1 | B13: Rolling 3-Month Premium Report | C13: A rolling window report: Start Month (input) | Months in window (input) | Rolling Total GWP | Rolling Average GWP | Rolling Total Claims | Rolling Loss Ratio. Changing the start month or the window size must move the whole report with no formula edits. | D13: Chief Financial Officer
A14: 2 | B14: Measure Switch for the one-page CFO summary | C14: The rolling report with a Measure selector cell (Gross Written Premium / Claims Paid / Net Premium Earned / Policies Issued). The column offset inside OFFSET must be driven by that cell. | D14: Head of Management Reporting
A15: 3 | B15: Quarter-on-quarter momentum table | C15: A momentum table: Window | Total GWP | Average GWP per month | Change vs previous window (PKR and %). Three windows: Jan-Mar, Apr-Jun, Jul-Sep, each built from the same OFFSET formula with a different start month cell. | D15: Regional Head — North
A16: 4 | B16: Performance memo on volatile functions | C16: A short memo in the yellow box: what 'volatile' means, why OFFSET slows a large workbook, and the non-volatile alternative you would use in a 200,000-row file. | D16: Head of MIS
A18: BUILD YOUR REPORT / OUTPUT BELOW (pivot, chart, macro output, or model — as required above)
A34: HOW TO WORK: build the requested output in the blank area above (or insert a pivot table / chart / macro-driven control here), tick each deliverable off in the checklist, and record any formula or setting worth remembering in the specification column.

Sheet 1.7 Data
A1: Dataset 1.7 — Handling Lookup Errors with IFERROR and IFNA
A2: Session 1: Advanced Lookup, Text & Date Functions | Part A: Advanced Lookup Functions | Adamjee Assurance Company Limited (Pakistan) — training data, figures in PKR
A4: Table A — Policy Master Extract
A5: Policy No | B5: Client Name | C5: Branch | D5: Gross Premium (PKR) | E5: Claims Paid (PKR)
A6: ADM-FIR-KHI-2024-1001 | B6: Gul Ahmed Textile Mills Ltd | C6: Karachi Main | D6: 96000 | E6: 120362
A7: ADM-TRV-LHR-2024-1002 | B7: Packages Limited | C7: Lahore Gulberg | D7: 201000 | E7: 206906
A8: ADM-MTR-ISB-2024-1003 | B8: Bilal Ahmed Khan | C8: Islamabad Blue Area | D8: 1397000 | E8: 400344
A9: ADM-HLT-FSD-2024-1004 | B9: Attock Refinery Limited | C9: Faisalabad | D9: 305000 | E9: 173654
A10: ADM-MSC-MUL-2024-1005 | B10: Descon Engineering Ltd | C10: Multan | D10: 75000 | E10: 26600
A11: ADM-MAR-PEW-2024-1006 | B11: Hina Farooq | C11: Peshawar | D11: 380000 | E11: 275064
A12: ADM-ENG-QTA-2024-1007 | B12: Indus Motor Company Ltd | C12: Quetta | D12: 227000 | E12: 227881
A13: ADM-FIR-HYD-2024-1008 | B13: Nishat Mills Limited | C13: Hyderabad | D13: 290000 | E13: 404928
A14: ADM-TRV-SKT-2024-1009 | B14: Imran Aslam Sheikh | C14: Sialkot | D14: 37000 | E14: 9893
A15: ADM-MTR-RWP-2024-1010 | B15: Engro Polymer & Chemicals | C15: Rawalpindi | D15: 760000 | E15: 483596
A16: ADM-HLT-KHI-2024-1011 | B16: Interloop Limited | C16: Karachi Main | D16: 603000 | E16: 775060
A17: ADM-MSC-LHR-2024-1012 | B17: Mehwish Anwar | C17: Lahore Gulberg | D17: 512000 | E17: 210598
... A25: ADM-MAR-RWP-2024-1020 | B25: Thal Limited | C25: Rawalpindi | D25: 181000 | E25: 145864
A27: Table B — Recovery Register (as received — contains bad references)
A28: Line | B28: Policy No Pasted | C28: Source Branch | D28: Status Noted
A29: 1 | B29: ADM-MTR-ISB-2024-1003 | C29: Karachi Main | D29: Valid
A30: 2 | B30: ADM-MTR-KHI-2024-9999 | C30: Karachi Main | D30: Cancelled policy
A31: 3 | B31: ADM-MAR-PEW-2024-1006 | C31: Lahore Gulberg | D31: Valid
A32: 4 | B32: ADM-TRV-SKT-2024-1009 | C32: Lahore Gulberg | D32: Trailing space typed
A33: 5 | B33: ADM-FIR-LHR-2023-0450 | C33: Lahore Gulberg | D33: Prior year – not in master
A34: 6 | B34: ADM-ENG-FSD-2024-1014 | C34: Islamabad Blue Area | D34: Valid
A35: 7 | C35: Islamabad Blue Area | D35: Blank cell pasted
A36: 8 | B36: ADM-HLT-HYD-2024-1018 | C36: Multan | D36: Valid
A38: Table C — Branch premium and claims for loss ratio (note the zero)
A39: Branch | B39: Gross Premium (PKR) | C39: Claims Paid (PKR)
A40: Karachi Main | B40: 48500000 | C40: 21300000
A41: Lahore Gulberg | B41: 33200000 | C41: 19900000
A42: Quetta (opened Dec-2024) | B42: 0 | C42: 0
A43: Multan | B43: 12700000 | C43: 8450000
A45: Note: This is simulated training data modelled on Adamjee Assurance general insurance operations. It is not actual company data.

Sheet 1.7 Report
A1: ADAMJEE ASSURANCE COMPANY LIMITED
A2: Recovery Register — cleaned for CFO signature
A3: Prepared for: | B3: Chief Financial Officer
A4: Prepared by:
A5: Reporting date: | B5: As at reporting date shown on the dataset
A7: The Recovery Register is compiled by pasting policy numbers from three branches. This month's draft went to the CFO with N/A in four rows and a DIV/0! in the branch summary. It came back unsigned with the comment 'I cannot present this to the Board'.
A9: Source data: '1.7 Data' (click to open)
A11: Navy headers below = data linked live from the dataset sheet. Gold headers = blank — build your formula here.
A12: Line | B12: Policy No | C12: Client Name | D12: Branch | E12: Gross Premium | F12: Status
B13: ='1.7 Data'!A6 | C13: ='1.7 Data'!B6 | D13: ='1.7 Data'!C6 | E13: ='1.7 Data'!D6
B14: ='1.7 Data'!A7 | C14: ='1.7 Data'!B7 | D14: ='1.7 Data'!C7 | E14: ='1.7 Data'!D7
B15: ='1.7 Data'!A8 | C15: ='1.7 Data'!B8 | D15: ='1.7 Data'!C8 | E15: ='1.7 Data'!D8
B16: ='1.7 Data'!A9 | C16: ='1.7 Data'!B9 | D16: ='1.7 Data'!C9 | E16: ='1.7 Data'!D9
B17: ='1.7 Data'!A10 | C17: ='1.7 Data'!B10 | D17: ='1.7 Data'!C10 | E17: ='1.7 Data'!D10
B18: ='1.7 Data'!A11 | C18: ='1.7 Data'!B11 | D18: ='1.7 Data'!C11 | E18: ='1.7 Data'!D11
B19: ='1.7 Data'!A12 | C19: ='1.7 Data'!B12 | D19: ='1.7 Data'!C12 | E19: ='1.7 Data'!D12
B20: ='1.7 Data'!A13 | C20: ='1.7 Data'!B13 | D20: ='1.7 Data'!C13 | E20: ='1.7 Data'!D13
B21: ='1.7 Data'!A14 | C21: ='1.7 Data'!B14 | D21: ='1.7 Data'!C14 | E21: ='1.7 Data'!D14
B22: ='1.7 Data'!A15 | C22: ='1.7 Data'!B15 | D22: ='1.7 Data'!C15 | E22: ='1.7 Data'!D15
B23: ='1.7 Data'!A16 | C23: ='1.7 Data'!B16 | D23: ='1.7 Data'!C16 | E23: ='1.7 Data'!D16
B24: ='1.7 Data'!A17 | C24: ='1.7 Data'!B17 | D24: ='1.7 Data'!C17 | E24: ='1.7 Data'!D17
... B32: ='1.7 Data'!A25 | C32: ='1.7 Data'!B25 | D32: ='1.7 Data'!C25 | E32: ='1.7 Data'!D25
A33: TOTAL / RESULT
A35: HOW TO WORK: navy-header columns are linked live from the dataset sheet — click any cell to see the formula. Gold-header columns are blank and shaded yellow — build the required formula there and copy it down every row, then complete the TOTAL / RESULT row at the foot.
A37: FURTHER REQUESTS ON THIS DATASET
A38: # | B38: Request | C38: Requested by | D38: Report / figure required | E38: Your formula or answer
A39: 1 | B39: Exception Schedule for the branch network | C39: Head of Internal Audit | D39: An exception schedule: Line | Policy No as pasted | Failure reason (Cancelled policy / Trailing space / Prior year / Blank cell) | Action for the branch. Count of exceptions shown at the top.
A40: 2 | B40: Recovering the trailing-space line without touching source data | C40: Manager, Policy Servicing | D40: The register with line 4 matching correctly, source data unchanged. Show the formula used and state in one line how many of the eight lines matched before and after your fix.
A41: 3 | B41: Branch Loss Ratio table including the new Quetta branch | C41: Regional Head — South | D41: A branch loss ratio table: Branch | GWP | Claims Paid | Loss Ratio, where a branch with no premium shows 'n/a' rather than an error. Ratios formatted 0.0%.
A42: 4 | B42: Control note on blanket error suppression | C42: Head of Internal Audit | D42: A three-line control note: why blanket IFERROR is dangerous in a financial report, the difference between IFERROR and IFNA, and your recommendation on which to use in the Recovery Register.

Sheet 1.8 Data
A1: Dataset 1.8 — LEFT, RIGHT, MID
A2: Session 1: Advanced Lookup, Text & Date Functions | Part B: Advanced Text Functions | Adamjee Assurance Company Limited (Pakistan) — training data, figures in PKR
A4: Table A — Policy Number Register (structure: ADM-PPP-BBB-YYYY-NNNN)
A5: Line | B5: Policy No | C5: Client Name | D5: Gross Premium (PKR)
A6: 1 | B6: ADM-MTR-KHI-2024-1001 | C6: Gul Ahmed Textile Mills Ltd | D6: 96000
A7: 2 | B7: ADM-FIR-KHI-2024-1002 | C7: Packages Limited | D7: 201000
A8: 3 | B8: ADM-MAR-KHI-2024-1003 | C8: Bilal Ahmed Khan | D8: 1397000
A9: 4 | B9: ADM-HLT-KHI-2024-1004 | C9: Attock Refinery Limited | D9: 305000
A10: 5 | B10: ADM-TRV-LHR-2024-1005 | C10: Descon Engineering Ltd | D10: 75000
A11: 6 | B11: ADM-ENG-LHR-2024-1006 | C11: Hina Farooq | D11: 380000
A12: 7 | B12: ADM-MSC-LHR-2024-1008 | C12: Indus Motor Company Ltd | D12: 227000
A13: 8 | B13: ADM-MTR-ISB-2024-1009 | C13: Nishat Mills Limited | D13: 290000
A14: 9 | B14: ADM-FIR-ISB-2024-1010 | C14: Imran Aslam Sheikh | D14: 37000
A15: 10 | B15: ADM-MAR-ISB-2024-1011 | C15: Engro Polymer & Chemicals | D15: 760000
A16: 11 | B16: ADM-HLT-FSD-2024-1012 | C16: Interloop Limited | D16: 603000
A17: 12 | B17: ADM-TRV-FSD-2024-1013 | C17: Mehwish Anwar | D17: 512000
... A29: 24 | B29: ADM-MAR-QTA-2024-1025 | C29: Ayesha Tariq | D29: 2304000
A31: Table B — Decode tables
A32: Product Code | B32: Product | C32: Branch Code | D32: Branch
A33: MTR | B33: Motor | C33: KHI | D33: Karachi Main
A34: FIR | B34: Fire & Property | C34: LHR | D34: Lahore Gulberg
A35: MAR | B35: Marine Cargo | C35: ISB | D35: Islamabad Blue Area
A36: HLT | B36: Health | C36: FSD | D36: Faisalabad
A37: TRV | B37: Travel | C37: MUL | D37: Multan
A38: ENG | B38: Engineering | C38: PEW | D38: Peshawar
A39: MSC | B39: Miscellaneous | C39: QTA | D39: Quetta
A41: Note: This is simulated training data modelled on Adamjee Assurance general insurance operations. It is not actual company data.

Sheet 1.8 Report
A1: ADAMJEE ASSURANCE COMPANY LIMITED
A2: Policy Register split into MIS dimensions
A3: Prepared for: | B3: Head of MIS
A4: Prepared by:
A5: Reporting date: | B5: As at reporting date shown on the dataset
A7: The data warehouse rebuild needs product and branch as separate fields. Today they exist only inside the policy number, and the interim solution has been a manual mapping file that a colleague updates by hand every month and which was last updated in June.
A9: Source data: '1.8 Data' (click to open)
A11: Navy headers below = data linked live from the dataset sheet. Gold headers = blank — build your formula here.
A12: Line | B12: Policy No | C12: Prefix | D12: Product Code | E12: Branch Code | F12: Year | G12: Serial | H12: Gross Premium
A13: ='1.8 Data'!A6 | B13: ='1.8 Data'!B6 | H13: ='1.8 Data'!D6
A14: ='1.8 Data'!A7 | B14: ='1.8 Data'!B7 | H14: ='1.8 Data'!D7
A15: ='1.8 Data'!A8 | B15: ='1.8 Data'!B8 | H15: ='1.8 Data'!D8
A16: ='1.8 Data'!A9 | B16: ='1.8 Data'!B9 | H16: ='1.8 Data'!D9
A17: ='1.8 Data'!A10 | B17: ='1.8 Data'!B10 | H17: ='1.8 Data'!D10
A18: ='1.8 Data'!A11 | B18: ='1.8 Data'!B11 | H18: ='1.8 Data'!D11
A19: ='1.8 Data'!A12 | B19: ='1.8 Data'!B12 | H19: ='1.8 Data'!D12
A20: ='1.8 Data'!A13 | B20: ='1.8 Data'!B13 | H20: ='1.8 Data'!D13
A21: ='1.8 Data'!A14 | B21: ='1.8 Data'!B14 | H21: ='1.8 Data'!D14
A22: ='1.8 Data'!A15 | B22: ='1.8 Data'!B15 | H22: ='1.8 Data'!D15
A23: ='1.8 Data'!A16 | B23: ='1.8 Data'!B16 | H23: ='1.8 Data'!D16
A24: ='1.8 Data'!A17 | B24: ='1.8 Data'!B17 | H24: ='1.8 Data'!D17
... A36: ='1.8 Data'!A29 | B36: ='1.8 Data'!B29 | H36: ='1.8 Data'!D29
A37: TOTAL / RESULT
A39: HOW TO WORK: navy-header columns are linked live from the dataset sheet — click any cell to see the formula. Gold-header columns are blank and shaded yellow — build the required formula there and copy it down every row, then complete the TOTAL / RESULT row at the foot.
A41: FURTHER REQUESTS ON THIS DATASET
A42: # | B42: Request | C42: Requested by | D42: Report / figure required | E42: Your formula or answer
A43: 1 | B43: Product and Branch names for the MIS extract | C43: Head of MIS | D43: The dimension table extended with Product Name and Branch Name columns, joined from the decode tables using your extracted codes.
A44: 2 | B44: Serial number continuity check | C44: Head of Internal Audit | D44: A continuity check: Branch Code | First Serial | Last Serial | Count of policies | Expected count | Gap flag. Serials must be real numbers, not text.
A45: 3 | B45: Format validation for the incoming feed | C45: Head of MIS | D45: A validation column flagging any policy number whose prefix is not exactly 'ADM', whose year is not 2024, or whose serial is not four digits. Count of failures shown at the top.

Sheet 1.9 Data
A1: Dataset 1.9 — FIND and SEARCH
A2: Session 1: Advanced Lookup, Text & Date Functions | Part B: Advanced Text Functions | Adamjee Assurance Company Limited (Pakistan) — training data, figures in PKR
A4: Table A — Claim Intimation Remarks (free text, positions vary)
A5: Claim No | B5: Branch | C5: Intimation Remark | D5: Claimed Amount (PKR)
A6: CLM-KHI-2024-0501 | B6: Karachi Main | C6: Vehicle Reg: AEE-1234 | Surveyor: Crawford Pakistan | Ref#45231 | D6: 385000
A7: CLM-LHR-2024-0502 | B7: Lahore Gulberg | C7: Vehicle Reg: LEB-8890 | Surveyor: Alpha Loss Adjusters | Ref#45298 | D7: 1240000
A8: CLM-ISB-2024-0503 | B8: Islamabad Blue Area | C8: Vehicle Reg: ICT-4471 | Surveyor: Rehman Surveyors Pvt Ltd | Ref#45310 | D8: 92500
A9: CLM-FSD-2024-0504 | B9: Faisalabad | C9: Vehicle Reg: FDR-2209 | Surveyor: Ravi Assessors | Ref#45344 | D9: 660000
A10: CLM-MUL-2024-0505 | B10: Multan | C10: vehicle reg: MNJ-7712 | surveyor: Sindh Survey Services | ref#45390 | D10: 208000
A11: CLM-KHI-2024-0506 | B11: Karachi Main | C11: Vehicle Reg: AKL-0056 | Surveyor: Crawford Pakistan | Ref#45412 | D11: 1875000
A12: CLM-PEW-2024-0507 | B12: Peshawar | C12: Vehicle Reg: PSR-3390 | Surveyor: Alpha Loss Adjusters | Ref#45457 | D12: 445000
A13: CLM-HYD-2024-0508 | B13: Hyderabad | C13: Vehicle Reg: HDA-6621 | Surveyor: Ravi Assessors | Ref#45501 | D13: 130000
A15: Note: This is simulated training data modelled on Adamjee Assurance general insurance operations. It is not actual company data.

Sheet 1.9 Report
A1: ADAMJEE ASSURANCE COMPANY LIMITED
A2: Motor Claims Intimation Register — fields extracted
A3: Prepared for: | B3: Manager, Motor Claims
A4: Prepared by:
A5: Reporting date: | B5: As at reporting date shown on the dataset
A7: Claim intimations arrive by email and the whole detail sits in one free-text remark field. The surveyor allocation report is currently produced by reading each remark and typing the three fields out, which takes an afternoon a week and is the reason surveyor workload is never accurate.
A9: Source data: '1.9 Data' (click to open)
A11: Navy headers below = data linked live from the dataset sheet. Gold headers = blank — build your formula here.
A12: Claim No | B12: Branch | C12: Vehicle Registration | D12: Surveyor Firm | E12: Reference No | F12: Claimed Amount
A13: ='1.9 Data'!A6 | B13: ='1.9 Data'!B6 | F13: ='1.9 Data'!D6
A14: ='1.9 Data'!A7 | B14: ='1.9 Data'!B7 | F14: ='1.9 Data'!D7
A15: ='1.9 Data'!A8 | B15: ='1.9 Data'!B8 | F15: ='1.9 Data'!D8
A16: ='1.9 Data'!A9 | B16: ='1.9 Data'!B9 | F16: ='1.9 Data'!D9
A17: ='1.9 Data'!A10 | B17: ='1.9 Data'!B10 | F17: ='1.9 Data'!D10
A18: ='1.9 Data'!A11 | B18: ='1.9 Data'!B11 | F18: ='1.9 Data'!D11
A19: ='1.9 Data'!A12 | B19: ='1.9 Data'!B12 | F19: ='1.9 Data'!D12
A20: ='1.9 Data'!A13 | B20: ='1.9 Data'!B13 | F20: ='1.9 Data'!D13
A21: TOTAL / RESULT
A23: HOW TO WORK: navy-header columns are linked live from the dataset sheet — click any cell to see the formula. Gold-header columns are blank and shaded yellow — build the required formula there and copy it down every row, then complete the TOTAL / RESULT row at the foot.
A25: FURTHER REQUESTS ON THIS DATASET
A26: # | B26: Request | C26: Requested by | D26: Report / figure required | E26: Your formula or answer
A27: 1 | B27: Surveyor Workload and Fee Accrual Report | C27: Head of Claims Operations | D27: A surveyor summary: Surveyor Firm | Cases Allocated | Total Claimed Amount | Average Claim Size | Share of cases %. Built on the extracted surveyor field, sorted by cases descending.
A28: 2 | B28: Case-sensitivity defect report | C28: Head of MIS | D28: A defect note plus the corrected formula: identify the affected row, state which of FIND and SEARCH failed and why, and show the formula that works for both upper and lower case.
A29: 3 | B29: Incomplete intimation exception list | C29: Manager, Motor Claims | D29: An exception list flagging any intimation whose remark does not contain the word 'Surveyor', with Claim No, Branch and the remark as received, plus a count at the top for the daily stand-up.

Sheet 1.10 Data
A1: Dataset 1.10 — LEN, TRIM, CLEAN
A2: Session 1: Advanced Lookup, Text & Date Functions | Part B: Advanced Text Functions | Adamjee Assurance Company Limited (Pakistan) — training data, figures in PKR
A4: Table A — Client names received from the bancassurance partner (dirty)
A5: Line | B5: Client Name (as received) | C5: CNIC / NTN | D5: Sum Insured (PKR)
A6: 1 | B6: Gul Ahmed Textile Mills Ltd | C6: 0713456-7 | D6: 45000000
A7: 2 | B7: Lucky Cement Limited | C7: 1234567-8 | D7: 88000000
A8: 3 | B8: Ahmed Raza Qureshi | C8: 42101-1234567-1 | D8: 6900000
A9: 4 | B9: Nishat Mills Limited | C9: 0918822-3 | D9: 62500000
A10: 5 | B10: Fatima Siddiqui | C10: 35202-9876543-2 | D10: 1950000
A11: 6 | B11: K-Electric Limited | C11: 0511223-4 | D11: 120000000
A12: 7 | B12: Interloop Limited | C12: 3301144-5 | D12: 22500000
A13: 8 | B13: Bilal Ahmed Khan | C13: 61101-4455667-9 | D13: 9990000
A15: Table B — Adamjee Policy Master (clean names, for matching)
A16: Client Name | B16: Client Code | C16: Branch | D16: Gross Premium (PKR)
A17: Gul Ahmed Textile Mills Ltd | B17: KHI-CORP-0100 | C17: Karachi Main | D17: 985000
A18: Lucky Cement Limited | B18: KHI-CORP-0102 | C18: Karachi Main | D18: 1640000
A19: Ahmed Raza Qureshi | B19: KHI-INDV-0107 | C19: Karachi Main | D19: 148000
A20: Nishat Mills Limited | B20: LHR-CORP-0111 | C20: Lahore Gulberg | D20: 1210000
A21: Fatima Siddiqui | B21: LHR-INDV-0113 | C21: Lahore Gulberg | D21: 46800
A22: K-Electric Limited | B22: KHI-CORP-0121 | C22: Karachi Main | D22: 3480000
A23: Interloop Limited | B23: FSD-CORP-0118 | C23: Faisalabad | D23: 720000
A24: Bilal Ahmed Khan | B24: ISB-INDV-0125 | C24: Islamabad Blue Area | D24: 205000
A26: Note: This is simulated training data modelled on Adamjee Assurance general insurance operations. It is not actual company data.

Sheet 1.10 Report
A1: ADAMJEE ASSURANCE COMPANY LIMITED
A2: Bancassurance Reconciliation — matched and unmatched
A3: Prepared for: | B3: Head of Bancassurance
A4: Prepared by:
A5: Reporting date: | B5: As at reporting date shown on the dataset
A7: The partner bank's monthly client file will not match the Adamjee policy master. On screen the names look identical, yet the lookup returns N/A on five of eight rows. The commission settlement with the bank is held up as a result and the relationship manager has escalated it twice.
A9: Source data: '1.10 Data' (click to open)
A11: Navy headers below = data linked live from the dataset sheet. Gold headers = blank — build your formula here.
A12: Line | B12: Name as received | C12: Character count | D12: Cleaned name | E12: Client Code matched | F12: Status (Matched / Unmatched)
A13: ='1.10 Data'!A6 | B13: ='1.10 Data'!B6
A14: ='1.10 Data'!A7 | B14: ='1.10 Data'!B7
A15: ='1.10 Data'!A8 | B15: ='1.10 Data'!B8
A16: ='1.10 Data'!A9 | B16: ='1.10 Data'!B9
A17: ='1.10 Data'!A10 | B17: ='1.10 Data'!B10
A18: ='1.10 Data'!A11 | B18: ='1.10 Data'!B11
A19: ='1.10 Data'!A12 | B19: ='1.10 Data'!B12
A20: ='1.10 Data'!A13 | B20: ='1.10 Data'!B13
A21: TOTAL / RESULT
A23: HOW TO WORK: navy-header columns are linked live from the dataset sheet — click any cell to see the formula. Gold-header columns are blank and shaded yellow — build the required formula there and copy it down every row, then complete the TOTAL / RESULT row at the foot.
A25: FURTHER REQUESTS ON THIS DATASET
A26: # | B26: Request | C26: Requested by | D26: Report / figure required | E26: Your formula or answer
A27: 1 | B27: Data quality defect log for the partner bank | C27: Head of Bancassurance | D27: A defect log: Line | Defect type (leading spaces / repeated inner spaces / trailing space / line feed / tab) | Extra characters counted | Example. One row per affected line, ready to attach to the email.
A28: 2 | B28: Commission settlement schedule | C28: Finance Manager — Premium Accounting | D28: A settlement schedule: Client Code | Client Name | Branch | Gross Premium | Commission due at 12.5% | Sum Insured from the bank file. Only matched rows included; unmatched rows listed separately below.
A29: 3 | B29: Source-system prevention recommendation | C29: Head of Bancassurance | D29: A two-line recommendation for the bank, in the yellow box: the single data-quality rule they should apply at source, and what Adamjee will do at its end as a safety net.

Sheet 1.11 Data
A1: Dataset 1.11 — SUBSTITUTE and REPLACE
A2: Session 1: Advanced Lookup, Text & Date Functions | Part B: Advanced Text Functions | Adamjee Assurance Company Limited (Pakistan) — training data, figures in PKR
A4: Table A — Legacy register requiring re-coding and masking
A5: Line | B5: Legacy Policy No | C5: Client Name | D5: CNIC | E5: Mobile | F5: Premium (PKR)
A6: 1 | B6: ADM-MTR-KHI-2022-1044 | C6: Gul Ahmed Textile Mills Ltd | D6: 42101-1234567-1 | E6: 0300-2345678 | F6: 985000
A7: 2 | B7: ADM-FIR-LHR-2022-1088 | C7: Nishat Mills Limited | D7: 35202-9876543-2 | E7: 0321-8765432 | F7: 1210000
A8: 3 | B8: ADM-MAR-KHI-2022-1120 | C8: Lucky Cement Limited | D8: 42201-5566778-3 | E8: 0333-1122334 | F8: 1640000
A9: 4 | B9: ADM-HLT-ISB-2022-1156 | C9: Bilal Ahmed Khan | D9: 61101-4455667-9 | E9: 0345-9988776 | F9: 205000
A10: 5 | B10: ADM-ENG-FSD-2022-1190 | C10: Interloop Limited | D10: 33100-2233445-7 | E10: 0301-4455667 | F10: 720000
A11: 6 | B11: ADM-MTR-LHR-2022-1215 | C11: Fatima Siddiqui | D11: 35201-7788990-4 | E11: 0312-3344556 | F11: 46800
A12: 7 | B12: ADM-TRV-KHI-2022-1240 | C12: Ahmed Raza Qureshi | D12: 42000-1029384-5 | E12: 0308-6677889 | F12: 148000
A13: 8 | B13: ADM-MSC-PEW-2022-1277 | C13: Descon Engineering Ltd | D13: 17301-5647382-6 | E13: 0311-2233445 | F13: 640000
A15: Table B — Branch re-coding map (old code to new code)
A16: Old Code | B16: New Code | C16: Branch
A17: KHI | B17: KHIM | C17: Karachi Main
A18: LHR | B18: LHGB | C18: Lahore Gulberg
A19: ISB | B19: ISBA | C19: Islamabad Blue Area
A20: FSD | B20: FSDC | C20: Faisalabad
A21: PEW | B21: PEWC | C21: Peshawar
A22: MUL | B22: MULC | C22: Multan
A24: Note: This is simulated training data modelled on Adamjee Assurance general insurance operations. It is not actual company data.

Sheet 1.11 Report
A1: ADAMJEE ASSURANCE COMPANY LIMITED
A2: Legacy Policy Re-coding Schedule
A3: Prepared for: | B3: Head of MIS
A4: Prepared by:
A5: Reporting date: | B5: As at reporting date shown on the dataset
A7: Adamjee has moved to four-letter branch codes. Eight thousand legacy policy numbers still carry the old three-letter codes and the migration date is the end of this month. The first attempt re-coded Lahore policies as Karachi because the mapping was applied by hand.
A9: Source data: '1.11 Data' (click to open)
A11: Navy headers below = data linked live from the dataset sheet. Gold headers = blank — build your formula here.
A12: Line | B12: Legacy Policy No | C12: New Policy No (year updated to 2025 and branch code converted) | D12: Old Code | E12: New Code | F12: Branch Name
A13: ='1.11 Data'!A6 | B13: ='1.11 Data'!B6
A14: ='1.11 Data'!A7 | B14: ='1.11 Data'!B7
A15: ='1.11 Data'!A8 | B15: ='1.11 Data'!B8
A16: ='1.11 Data'!A9 | B16: ='1.11 Data'!B9
A17: ='1.11 Data'!A10 | B17: ='1.11 Data'!B10
A18: ='1.11 Data'!A11 | B18: ='1.11 Data'!B11
A19: ='1.11 Data'!A12 | B19: ='1.11 Data'!B12
A20: ='1.11 Data'!A13 | B20: ='1.11 Data'!B13
A21: TOTAL / RESULT
A23: HOW TO WORK: navy-header columns are linked live from the dataset sheet — click any cell to see the formula. Gold-header columns are blank and shaded yellow — build the required formula there and copy it down every row, then complete the TOTAL / RESULT row at the foot.
A25: FURTHER REQUESTS ON THIS DATASET
A26: # | B26: Request | C26: Requested by | D26: Report / figure required | E26: Your formula or answer
A27: 1 | B27: Masked Client Register for the external surveyor | C27: Head of Compliance | D27: A masked register: Line | Policy No | Client Name | CNIC masked to show only the final digit | Mobile masked to show only the network prefix | Premium. Nothing typed by hand — every mask produced by formula.
A28: 2 | B28: Product line re-designation for the SECP return | C28: Head of Regulatory Reporting | D28: A return extract: Original Policy No | Return Policy No (characters 5-7 replaced with GEN) | Product | Premium. The original column must remain visible for reconciliation.
A29: 3 | B29: Method selection note for the migration runbook | C29: Head of MIS | D29: A two-line entry for the runbook: when to use SUBSTITUTE and when to use REPLACE, with one Adamjee example of each from the work you just did.

Sheet 1.12 Data
A1: Dataset 1.12 — CONCATENATE and the Ampersand (&) Operator
A2: Session 1: Advanced Lookup, Text & Date Functions | Part B: Advanced Text Functions | Adamjee Assurance Company Limited (Pakistan) — training data, figures in PKR
A4: Table A — Renewal campaign base data
A5: Client Code | B5: Title | C5: Client Name | D5: Address Line | E5: City | F5: Product Code | G5: Branch Code | H5: Policy Serial | I5: Renewal Date | J5: Renewal Premium (PKR)
A6: KHI-CORP-0100 | B6: M/s | C6: Gul Ahmed Textile Mills Ltd | D6: Plot 82, Korangi Industrial Area | E6: Karachi | F6: MTR | G6: KHI | H6: 1044 | I6: 45672 | J6: 1085000
A7: LHR-CORP-0111 | B7: M/s | C7: Nishat Mills Limited | D7: 7-Main Gulberg | E7: Lahore | F7: FIR | G7: LHR | H7: 1088 | I7: 45689 | J7: 1330000
A8: KHI-CORP-0102 | B8: M/s | C8: Lucky Cement Limited | D8: Main Shahrah-e-Faisal | E8: Karachi | F8: MAR | G8: KHI | H8: 1120 | I8: 45706 | J8: 1805000
A9: ISB-INDV-0125 | B9: Mr. | C9: Bilal Ahmed Khan | D9: House 44, Street 6, F-8/3 | E9: Islamabad | F9: HLT | G9: ISB | H9: 1156 | I9: 45720 | J9: 225000
A10: FSD-CORP-0118 | B10: M/s | C10: Interloop Limited | D10: Khurrianwala-Jaranwala Road | E10: Faisalabad | F10: ENG | G10: FSD | H10: 1190 | I10: 45737 | J10: 792000
A11: LHR-INDV-0113 | B11: Ms. | C11: Fatima Siddiqui | D11: 12-C Model Town Link Road | E11: Lahore | F11: MTR | G11: LHR | H11: 1215 | I11: 45756 | J11: 51400
A12: KHI-INDV-0107 | B12: Mr. | C12: Ahmed Raza Qureshi | D12: Flat 301, Block 6 PECHS | E12: Karachi | F12: TRV | G12: KHI | H12: 1240 | I12: 45774 | J12: 162000
